[04/Apr/2016 11:02:03] ERROR [django.request:256] Internal Server Error: /
Traceback (most recent call last):
  File "/Users/Afxal/workspace/wedi/lib/python2.7/site-packages/django/core/handlers/base.py", line 119, in get_response
    resolver_match = resolver.resolve(request.path_info)
  File "/Users/Afxal/workspace/wedi/lib/python2.7/site-packages/django/core/urlresolvers.py", line 365, in resolve
    for pattern in self.url_patterns:
  File "/Users/Afxal/workspace/wedi/lib/python2.7/site-packages/django/core/urlresolvers.py", line 401, in url_patterns
    patterns = getattr(self.urlconf_module, "urlpatterns", self.urlconf_module)
  File "/Users/Afxal/workspace/wedi/lib/python2.7/site-packages/django/core/urlresolvers.py", line 395, in urlconf_module
    self._urlconf_module = import_module(self.urlconf_name)
  File "/System/Library/Frameworks/Python.framework/Versions/2.7/lib/python2.7/importlib/__init__.py", line 37, in import_module
    __import__(name)
  File "/Users/Afxal/workspace/test_project/main/urls.py", line 11, in <module>
    url(r'^home/', include('app.home.urls')),
  File "/Users/Afxal/workspace/wedi/lib/python2.7/site-packages/django/conf/urls/__init__.py", line 33, in include
    urlconf_module = import_module(urlconf_module)
  File "/System/Library/Frameworks/Python.framework/Versions/2.7/lib/python2.7/importlib/__init__.py", line 37, in import_module
    __import__(name)
  File "/Users/Afxal/workspace/test_project/app/home/urls.py", line 6, in <module>
    url(r'abc/$', views.faq, name='index'),
AttributeError: 'module' object has no attribute 'faq'
[04/Apr/2016 11:02:17] WARNING [django.request:170] Not Found: /
[04/Apr/2016 11:02:17] WARNING [django.request:170] Not Found: /
[04/Apr/2016 11:02:55] INFO [gunicorn.error:224] Worker reloading: /Users/Afxal/workspace/test_project/app/home/urls.py modified
[04/Apr/2016 11:02:55] INFO [gunicorn.error:224] Worker reloading: /Users/Afxal/workspace/test_project/app/home/urls.py modified
[04/Apr/2016 11:02:55] INFO [gunicorn.error:224] Worker exiting (pid: 14524)
[04/Apr/2016 11:02:55] INFO [gunicorn.error:224] Worker exiting (pid: 14524)
[04/Apr/2016 11:08:42] ERROR [django.request:256] Internal Server Error: /
Traceback (most recent call last):
  File "/Users/Afxal/workspace/wedi/lib/python2.7/site-packages/django/core/handlers/base.py", line 119, in get_response
    resolver_match = resolver.resolve(request.path_info)
  File "/Users/Afxal/workspace/wedi/lib/python2.7/site-packages/django/core/urlresolvers.py", line 365, in resolve
    for pattern in self.url_patterns:
  File "/Users/Afxal/workspace/wedi/lib/python2.7/site-packages/django/core/urlresolvers.py", line 401, in url_patterns
    patterns = getattr(self.urlconf_module, "urlpatterns", self.urlconf_module)
  File "/Users/Afxal/workspace/wedi/lib/python2.7/site-packages/django/core/urlresolvers.py", line 395, in urlconf_module
    self._urlconf_module = import_module(self.urlconf_name)
  File "/System/Library/Frameworks/Python.framework/Versions/2.7/lib/python2.7/importlib/__init__.py", line 37, in import_module
    __import__(name)
  File "/Users/Afxal/workspace/test_project/main/urls.py", line 11, in <module>
    url(r'^home/', include('app.home.urls')),
  File "/Users/Afxal/workspace/wedi/lib/python2.7/site-packages/django/conf/urls/__init__.py", line 33, in include
    urlconf_module = import_module(urlconf_module)
  File "/System/Library/Frameworks/Python.framework/Versions/2.7/lib/python2.7/importlib/__init__.py", line 37, in import_module
    __import__(name)
  File "/Users/Afxal/workspace/test_project/app/home/urls.py", line 6, in <module>
    url(r'^$', views.index, name='index'),
AttributeError: 'module' object has no attribute 'index'
[04/Apr/2016 11:08:50] INFO [gunicorn.error:224] Worker reloading: /Users/Afxal/workspace/test_project/app/home/views.py modified
[04/Apr/2016 11:08:50] INFO [gunicorn.error:224] Worker reloading: /Users/Afxal/workspace/test_project/app/home/views.py modified
[04/Apr/2016 11:08:51] INFO [gunicorn.error:224] Worker exiting (pid: 14573)
[04/Apr/2016 11:08:51] INFO [gunicorn.error:224] Worker exiting (pid: 14573)
[04/Apr/2016 11:08:54] WARNING [django.request:170] Not Found: /
[04/Apr/2016 11:08:55] WARNING [django.request:170] Not Found: /
[04/Apr/2016 11:12:01] INFO [gunicorn.error:224] Worker reloading: /Users/Afxal/workspace/test_project/app/home/views.py modified
[04/Apr/2016 11:12:01] INFO [gunicorn.error:224] Worker reloading: /Users/Afxal/workspace/test_project/app/home/views.py modified
[04/Apr/2016 11:12:01] INFO [gunicorn.error:224] Worker exiting (pid: 14598)
[04/Apr/2016 11:12:01] INFO [gunicorn.error:224] Worker exiting (pid: 14598)
[04/Apr/2016 11:30:23] INFO [gunicorn.error:224] Worker exiting (pid: 14603)
[04/Apr/2016 11:30:23] INFO [gunicorn.error:224] Worker exiting (pid: 14603)
[04/Apr/2016 11:38:54] INFO [gunicorn.error:224] Worker exiting (pid: 14634)
[04/Apr/2016 11:38:54] INFO [gunicorn.error:224] Worker exiting (pid: 14634)
[04/Apr/2016 11:48:20] INFO [gunicorn.error:224] Worker exiting (pid: 14638)
[04/Apr/2016 11:48:20] INFO [gunicorn.error:224] Worker exiting (pid: 14638)
[04/Apr/2016 12:03:55] INFO [gunicorn.error:224] Worker exiting (pid: 14657)
[04/Apr/2016 12:03:55] INFO [gunicorn.error:224] Worker exiting (pid: 14657)
[04/Apr/2016 12:12:49] INFO [gunicorn.error:224] Worker exiting (pid: 14801)
[04/Apr/2016 12:12:49] INFO [gunicorn.error:224] Worker exiting (pid: 14801)
[04/Apr/2016 12:16:06] WARNING [django.request:170] Not Found: /
[04/Apr/2016 12:16:07] WARNING [django.request:170] Not Found: /
[04/Apr/2016 12:19:07] INFO [gunicorn.error:224] Worker exiting (pid: 14981)
[04/Apr/2016 12:19:07] INFO [gunicorn.error:224] Worker exiting (pid: 14981)
[04/Apr/2016 12:23:32] WARNING [django.request:170] Not Found: /home/static/home/js/angular.js
[04/Apr/2016 12:24:01] WARNING [django.request:170] Not Found: /home/static/home/js/angular.js
[04/Apr/2016 12:24:17] WARNING [django.request:170] Not Found: /home/static/home/js/angular.js
[04/Apr/2016 12:24:19] WARNING [django.request:170] Not Found: /home/static/home/js/angular.js
[04/Apr/2016 12:24:22] INFO [gunicorn.error:224] Worker exiting (pid: 15004)
[04/Apr/2016 12:24:22] INFO [gunicorn.error:224] Worker exiting (pid: 15004)
[04/Apr/2016 12:24:37] WARNING [django.request:170] Not Found: /home/static/home/js/angular.js
[04/Apr/2016 12:26:14] WARNING [django.request:170] Not Found: /
[04/Apr/2016 12:28:17] INFO [gunicorn.error:224] Worker exiting (pid: 15013)
[04/Apr/2016 12:28:17] INFO [gunicorn.error:224] Worker exiting (pid: 15013)
[04/Apr/2016 12:36:18] INFO [gunicorn.error:224] Worker exiting (pid: 15038)
[04/Apr/2016 12:36:18] INFO [gunicorn.error:224] Worker exiting (pid: 15038)
[04/Apr/2016 12:36:39] INFO [gunicorn.error:224] Worker exiting (pid: 15068)
[04/Apr/2016 12:36:39] INFO [gunicorn.error:224] Worker exiting (pid: 15068)
[04/Apr/2016 13:13:53] INFO [gunicorn.error:224] Worker exiting (pid: 15087)
[04/Apr/2016 13:13:53] INFO [gunicorn.error:224] Worker exiting (pid: 15087)
[04/Apr/2016 13:21:19] INFO [gunicorn.error:224] Worker exiting (pid: 15169)
[04/Apr/2016 13:21:19] INFO [gunicorn.error:224] Worker exiting (pid: 15169)
[04/Apr/2016 13:34:41] INFO [gunicorn.error:224] Worker exiting (pid: 15188)
[04/Apr/2016 13:34:41] INFO [gunicorn.error:224] Worker exiting (pid: 15188)
[04/Apr/2016 14:09:21] INFO [gunicorn.error:224] Worker exiting (pid: 19897)
[04/Apr/2016 14:09:21] INFO [gunicorn.error:224] Worker exiting (pid: 19897)
[04/Apr/2016 14:48:48] INFO [gunicorn.error:224] Worker exiting (pid: 20025)
[04/Apr/2016 14:48:48] INFO [gunicorn.error:224] Worker exiting (pid: 20025)
[04/Apr/2016 14:57:41] INFO [gunicorn.error:224] Worker exiting (pid: 20059)
[04/Apr/2016 14:57:41] INFO [gunicorn.error:224] Worker exiting (pid: 20059)
[04/Apr/2016 15:02:37] INFO [gunicorn.error:224] Worker exiting (pid: 20087)
[04/Apr/2016 15:02:37] INFO [gunicorn.error:224] Worker exiting (pid: 20087)
[04/Apr/2016 18:10:00] INFO [gunicorn.error:224] Worker exiting (pid: 20103)
[04/Apr/2016 18:10:00] INFO [gunicorn.error:224] Worker exiting (pid: 20103)
[05/Apr/2016 04:37:28] INFO [gunicorn.error:224] Worker exiting (pid: 20194)
[05/Apr/2016 04:37:28] INFO [gunicorn.error:224] Worker exiting (pid: 20194)
[05/Apr/2016 05:13:55] INFO [gunicorn.error:224] Worker exiting (pid: 20224)
[05/Apr/2016 05:13:55] INFO [gunicorn.error:224] Worker exiting (pid: 20224)
[05/Apr/2016 05:19:12] WARNING [django.request:170] Not Found: /
[05/Apr/2016 05:34:27] INFO [gunicorn.error:224] Worker exiting (pid: 20402)
[05/Apr/2016 05:34:27] INFO [gunicorn.error:224] Worker exiting (pid: 20402)
[05/Apr/2016 06:13:16] INFO [gunicorn.error:224] Worker exiting (pid: 20782)
[05/Apr/2016 06:13:16] INFO [gunicorn.error:224] Worker exiting (pid: 20782)
[05/Apr/2016 06:23:15] INFO [gunicorn.error:224] Worker exiting (pid: 21121)
[05/Apr/2016 06:23:15] INFO [gunicorn.error:224] Worker exiting (pid: 21121)
[05/Apr/2016 07:03:56] INFO [gunicorn.error:224] Worker exiting (pid: 21268)
[05/Apr/2016 07:03:56] INFO [gunicorn.error:224] Worker exiting (pid: 21268)
[05/Apr/2016 07:12:21] INFO [gunicorn.error:224] Worker exiting (pid: 21584)
[05/Apr/2016 07:12:21] INFO [gunicorn.error:224] Worker exiting (pid: 21584)
[05/Apr/2016 07:42:36] INFO [gunicorn.error:224] Worker exiting (pid: 21864)
[05/Apr/2016 07:42:36] INFO [gunicorn.error:224] Worker exiting (pid: 21864)
[18/May/2018 15:39:04] ERROR [django.request:284] Internal Server Error: /
Traceback (most recent call last):
  File "/Users/afsal/workspace/env_movie/lib/python2.7/site-packages/django/core/handlers/base.py", line 149, in get_response
    response = self.process_exception_by_middleware(e, request)
  File "/Users/afsal/workspace/env_movie/lib/python2.7/site-packages/django/core/handlers/base.py", line 147, in get_response
    response = wrapped_callback(request, *callback_args, **callback_kwargs)
  File "/Users/afsal/workspace/movieList/app/home/views.py", line 4, in index
    return render(request,'home/index.html')
  File "/Users/afsal/workspace/env_movie/lib/python2.7/site-packages/django/shortcuts.py", line 67, in render
    template_name, context, request=request, using=using)
  File "/Users/afsal/workspace/env_movie/lib/python2.7/site-packages/django/template/loader.py", line 97, in render_to_string
    return template.render(context, request)
  File "/Users/afsal/workspace/env_movie/lib/python2.7/site-packages/django/template/backends/django.py", line 95, in render
    return self.template.render(context)
  File "/Users/afsal/workspace/env_movie/lib/python2.7/site-packages/django/template/base.py", line 204, in render
    with context.bind_template(self):
  File "/System/Library/Frameworks/Python.framework/Versions/2.7/lib/python2.7/contextlib.py", line 17, in __enter__
    return self.gen.next()
  File "/Users/afsal/workspace/env_movie/lib/python2.7/site-packages/django/template/context.py", line 256, in bind_template
    processors = (template.engine.template_context_processors +
  File "/Users/afsal/workspace/env_movie/lib/python2.7/site-packages/django/utils/functional.py", line 33, in __get__
    res = instance.__dict__[self.name] = self.func(instance)
  File "/Users/afsal/workspace/env_movie/lib/python2.7/site-packages/django/template/engine.py", line 105, in template_context_processors
    return tuple(import_string(path) for path in context_processors)
  File "/Users/afsal/workspace/env_movie/lib/python2.7/site-packages/django/template/engine.py", line 105, in <genexpr>
    return tuple(import_string(path) for path in context_processors)
  File "/Users/afsal/workspace/env_movie/lib/python2.7/site-packages/django/utils/module_loading.py", line 20, in import_string
    module = import_module(module_path)
  File "/System/Library/Frameworks/Python.framework/Versions/2.7/lib/python2.7/importlib/__init__.py", line 37, in import_module
    __import__(name)
  File "/Users/afsal/workspace/env_movie/lib/python2.7/site-packages/social/apps/django_app/context_processors.py", line 1, in <module>
    from social_django.context_processors import LazyDict, backends, login_redirect
ImportError: No module named social_django.context_processors
[18/May/2018 15:39:07] WARNING [django.request:182] Not Found: /favicon.ico
[18/May/2018 15:58:46] WARNING [django.request:182] Not Found: /admin
[18/May/2018 15:59:26] WARNING [django.request:182] Not Found: /admin
[18/May/2018 17:49:35] ERROR [django.request:284] Internal Server Error: /
Traceback (most recent call last):
  File "/Users/afsal/workspace/env_movie/lib/python2.7/site-packages/django/core/handlers/base.py", line 149, in get_response
    response = self.process_exception_by_middleware(e, request)
  File "/Users/afsal/workspace/env_movie/lib/python2.7/site-packages/django/core/handlers/base.py", line 147, in get_response
    response = wrapped_callback(request, *callback_args, **callback_kwargs)
  File "/Users/afsal/workspace/movieList/app/home/views.py", line 6, in index
    from BeautifulSoup import BeautifulSoup
ImportError: No module named BeautifulSoup
[18/May/2018 17:49:37] WARNING [django.request:182] Not Found: /favicon.ico
[18/May/2018 17:50:34] ERROR [django.request:284] Internal Server Error: /
Traceback (most recent call last):
  File "/Users/afsal/workspace/env_movie/lib/python2.7/site-packages/django/core/handlers/base.py", line 149, in get_response
    response = self.process_exception_by_middleware(e, request)
  File "/Users/afsal/workspace/env_movie/lib/python2.7/site-packages/django/core/handlers/base.py", line 147, in get_response
    response = wrapped_callback(request, *callback_args, **callback_kwargs)
  File "/Users/afsal/workspace/movieList/app/home/views.py", line 9, in index
    print(soup)
NameError: global name 'soup' is not defined
[18/May/2018 17:55:21] ERROR [django.request:284] Internal Server Error: /
Traceback (most recent call last):
  File "/Users/afsal/workspace/env_movie/lib/python2.7/site-packages/django/core/handlers/base.py", line 149, in get_response
    response = self.process_exception_by_middleware(e, request)
  File "/Users/afsal/workspace/env_movie/lib/python2.7/site-packages/django/core/handlers/base.py", line 147, in get_response
    response = wrapped_callback(request, *callback_args, **callback_kwargs)
  File "/Users/afsal/workspace/movieList/app/home/views.py", line 13, in index
    print(anchor['href'].index(".mkv"))
ValueError: substring not found
[18/May/2018 17:56:33] ERROR [django.request:284] Internal Server Error: /
Traceback (most recent call last):
  File "/Users/afsal/workspace/env_movie/lib/python2.7/site-packages/django/core/handlers/base.py", line 149, in get_response
    response = self.process_exception_by_middleware(e, request)
  File "/Users/afsal/workspace/env_movie/lib/python2.7/site-packages/django/core/handlers/base.py", line 147, in get_response
    response = wrapped_callback(request, *callback_args, **callback_kwargs)
  File "/Users/afsal/workspace/movieList/app/home/views.py", line 13, in index
    print(anchor['href'].index(".."))
ValueError: substring not found
[18/May/2018 17:58:06] ERROR [django.request:284] Internal Server Error: /
Traceback (most recent call last):
  File "/Users/afsal/workspace/env_movie/lib/python2.7/site-packages/django/core/handlers/base.py", line 149, in get_response
    response = self.process_exception_by_middleware(e, request)
  File "/Users/afsal/workspace/env_movie/lib/python2.7/site-packages/django/core/handlers/base.py", line 147, in get_response
    response = wrapped_callback(request, *callback_args, **callback_kwargs)
  File "/Users/afsal/workspace/movieList/app/home/views.py", line 13, in index
    print(anchor['href'].index(".///"))
ValueError: substring not found
[18/May/2018 17:58:11] ERROR [django.request:284] Internal Server Error: /
Traceback (most recent call last):
  File "/Users/afsal/workspace/env_movie/lib/python2.7/site-packages/django/core/handlers/base.py", line 149, in get_response
    response = self.process_exception_by_middleware(e, request)
  File "/Users/afsal/workspace/env_movie/lib/python2.7/site-packages/django/core/handlers/base.py", line 147, in get_response
    response = wrapped_callback(request, *callback_args, **callback_kwargs)
  File "/Users/afsal/workspace/movieList/app/home/views.py", line 13, in index
    print(anchor['href'].index(".///"))
ValueError: substring not found
[18/May/2018 18:03:13] ERROR [django.request:284] Internal Server Error: /
Traceback (most recent call last):
  File "/Users/afsal/workspace/env_movie/lib/python2.7/site-packages/django/core/handlers/base.py", line 149, in get_response
    response = self.process_exception_by_middleware(e, request)
  File "/Users/afsal/workspace/env_movie/lib/python2.7/site-packages/django/core/handlers/base.py", line 147, in get_response
    response = wrapped_callback(request, *callback_args, **callback_kwargs)
  File "/Users/afsal/workspace/movieList/app/home/views.py", line 11, in index
    log.info(urllib2.urlopen(url))
NameError: global name 'log' is not defined
[18/May/2018 18:05:10] ERROR [django.request:284] Internal Server Error: /
Traceback (most recent call last):
  File "/Users/afsal/workspace/env_movie/lib/python2.7/site-packages/django/core/handlers/base.py", line 149, in get_response
    response = self.process_exception_by_middleware(e, request)
  File "/Users/afsal/workspace/env_movie/lib/python2.7/site-packages/django/core/handlers/base.py", line 147, in get_response
    response = wrapped_callback(request, *callback_args, **callback_kwargs)
  File "/Users/afsal/workspace/movieList/app/home/views.py", line 11, in index
    print(urllib2.urlopen(url))
  File "/System/Library/Frameworks/Python.framework/Versions/2.7/lib/python2.7/urllib2.py", line 154, in urlopen
    return opener.open(url, data, timeout)
  File "/System/Library/Frameworks/Python.framework/Versions/2.7/lib/python2.7/urllib2.py", line 437, in open
    response = meth(req, response)
  File "/System/Library/Frameworks/Python.framework/Versions/2.7/lib/python2.7/urllib2.py", line 550, in http_response
    'http', request, response, code, msg, hdrs)
  File "/System/Library/Frameworks/Python.framework/Versions/2.7/lib/python2.7/urllib2.py", line 475, in error
    return self._call_chain(*args)
  File "/System/Library/Frameworks/Python.framework/Versions/2.7/lib/python2.7/urllib2.py", line 409, in _call_chain
    result = func(*args)
  File "/System/Library/Frameworks/Python.framework/Versions/2.7/lib/python2.7/urllib2.py", line 558, in http_error_default
    raise HTTPError(req.get_full_url(), code, msg, hdrs, fp)
HTTPError: HTTP Error 404: Not Found
[18/May/2018 18:20:42] ERROR [django.request:284] Internal Server Error: /
Traceback (most recent call last):
  File "/Users/afsal/workspace/env_movie/lib/python2.7/site-packages/django/core/handlers/base.py", line 149, in get_response
    response = self.process_exception_by_middleware(e, request)
  File "/Users/afsal/workspace/env_movie/lib/python2.7/site-packages/django/core/handlers/base.py", line 147, in get_response
    response = wrapped_callback(request, *callback_args, **callback_kwargs)
  File "/Users/afsal/workspace/movieList/app/home/views.py", line 17, in index
    season = Season.objects.get_or_create(series=series,url=url, name='Series {1:02d}'.format(i))
IndexError: tuple index out of range
[18/May/2018 18:21:41] ERROR [django.request:284] Internal Server Error: /
Traceback (most recent call last):
  File "/Users/afsal/workspace/env_movie/lib/python2.7/site-packages/django/core/handlers/base.py", line 149, in get_response
    response = self.process_exception_by_middleware(e, request)
  File "/Users/afsal/workspace/env_movie/lib/python2.7/site-packages/django/core/handlers/base.py", line 147, in get_response
    response = wrapped_callback(request, *callback_args, **callback_kwargs)
  File "/Users/afsal/workspace/movieList/app/home/views.py", line 17, in index
    season = Season.objects.get_or_create(series=series,url=url, name='Series {0:02d}'.format(i))
  File "/Users/afsal/workspace/env_movie/lib/python2.7/site-packages/django/db/models/manager.py", line 122, in manager_method
    return getattr(self.get_queryset(), name)(*args, **kwargs)
  File "/Users/afsal/workspace/env_movie/lib/python2.7/site-packages/django/db/models/query.py", line 465, in get_or_create
    return self.get(**lookup), False
  File "/Users/afsal/workspace/env_movie/lib/python2.7/site-packages/django/db/models/query.py", line 378, in get
    clone = self.filter(*args, **kwargs)
  File "/Users/afsal/workspace/env_movie/lib/python2.7/site-packages/django/db/models/query.py", line 790, in filter
    return self._filter_or_exclude(False, *args, **kwargs)
  File "/Users/afsal/workspace/env_movie/lib/python2.7/site-packages/django/db/models/query.py", line 808, in _filter_or_exclude
    clone.query.add_q(Q(*args, **kwargs))
  File "/Users/afsal/workspace/env_movie/lib/python2.7/site-packages/django/db/models/sql/query.py", line 1243, in add_q
    clause, _ = self._add_q(q_object, self.used_aliases)
  File "/Users/afsal/workspace/env_movie/lib/python2.7/site-packages/django/db/models/sql/query.py", line 1269, in _add_q
    allow_joins=allow_joins, split_subq=split_subq,
  File "/Users/afsal/workspace/env_movie/lib/python2.7/site-packages/django/db/models/sql/query.py", line 1199, in build_filter
    condition = lookup_class(lhs, value)
  File "/Users/afsal/workspace/env_movie/lib/python2.7/site-packages/django/db/models/lookups.py", line 19, in __init__
    self.rhs = self.get_prep_lookup()
  File "/Users/afsal/workspace/env_movie/lib/python2.7/site-packages/django/db/models/fields/related_lookups.py", line 99, in get_prep_lookup
    self.lookup_name, self.rhs)
  File "/Users/afsal/workspace/env_movie/lib/python2.7/site-packages/django/db/models/fields/__init__.py", line 744, in get_prep_lookup
    return self.get_prep_value(value)
  File "/Users/afsal/workspace/env_movie/lib/python2.7/site-packages/django/db/models/fields/__init__.py", line 976, in get_prep_value
    return int(value)
TypeError: int() argument must be a string or a number, not 'Series'
[18/May/2018 18:22:09] ERROR [django.request:284] Internal Server Error: /
Traceback (most recent call last):
  File "/Users/afsal/workspace/env_movie/lib/python2.7/site-packages/django/core/handlers/base.py", line 149, in get_response
    response = self.process_exception_by_middleware(e, request)
  File "/Users/afsal/workspace/env_movie/lib/python2.7/site-packages/django/core/handlers/base.py", line 147, in get_response
    response = wrapped_callback(request, *callback_args, **callback_kwargs)
  File "/Users/afsal/workspace/movieList/app/home/views.py", line 17, in index
    season = Season.objects.get_or_create(series=series,url=url, name='Series {0}'.format(i))
  File "/Users/afsal/workspace/env_movie/lib/python2.7/site-packages/django/db/models/manager.py", line 122, in manager_method
    return getattr(self.get_queryset(), name)(*args, **kwargs)
  File "/Users/afsal/workspace/env_movie/lib/python2.7/site-packages/django/db/models/query.py", line 465, in get_or_create
    return self.get(**lookup), False
  File "/Users/afsal/workspace/env_movie/lib/python2.7/site-packages/django/db/models/query.py", line 378, in get
    clone = self.filter(*args, **kwargs)
  File "/Users/afsal/workspace/env_movie/lib/python2.7/site-packages/django/db/models/query.py", line 790, in filter
    return self._filter_or_exclude(False, *args, **kwargs)
  File "/Users/afsal/workspace/env_movie/lib/python2.7/site-packages/django/db/models/query.py", line 808, in _filter_or_exclude
    clone.query.add_q(Q(*args, **kwargs))
  File "/Users/afsal/workspace/env_movie/lib/python2.7/site-packages/django/db/models/sql/query.py", line 1243, in add_q
    clause, _ = self._add_q(q_object, self.used_aliases)
  File "/Users/afsal/workspace/env_movie/lib/python2.7/site-packages/django/db/models/sql/query.py", line 1269, in _add_q
    allow_joins=allow_joins, split_subq=split_subq,
  File "/Users/afsal/workspace/env_movie/lib/python2.7/site-packages/django/db/models/sql/query.py", line 1199, in build_filter
    condition = lookup_class(lhs, value)
  File "/Users/afsal/workspace/env_movie/lib/python2.7/site-packages/django/db/models/lookups.py", line 19, in __init__
    self.rhs = self.get_prep_lookup()
  File "/Users/afsal/workspace/env_movie/lib/python2.7/site-packages/django/db/models/fields/related_lookups.py", line 99, in get_prep_lookup
    self.lookup_name, self.rhs)
  File "/Users/afsal/workspace/env_movie/lib/python2.7/site-packages/django/db/models/fields/__init__.py", line 744, in get_prep_lookup
    return self.get_prep_value(value)
  File "/Users/afsal/workspace/env_movie/lib/python2.7/site-packages/django/db/models/fields/__init__.py", line 976, in get_prep_value
    return int(value)
TypeError: int() argument must be a string or a number, not 'Series'
[18/May/2018 18:22:55] ERROR [django.request:284] Internal Server Error: /
Traceback (most recent call last):
  File "/Users/afsal/workspace/env_movie/lib/python2.7/site-packages/django/core/handlers/base.py", line 149, in get_response
    response = self.process_exception_by_middleware(e, request)
  File "/Users/afsal/workspace/env_movie/lib/python2.7/site-packages/django/core/handlers/base.py", line 147, in get_response
    response = wrapped_callback(request, *callback_args, **callback_kwargs)
  File "/Users/afsal/workspace/movieList/app/home/views.py", line 17, in index
    season = Season.objects.get_or_create(series=series,url=url, name='Series {0}'.format(str(i)))
  File "/Users/afsal/workspace/env_movie/lib/python2.7/site-packages/django/db/models/manager.py", line 122, in manager_method
    return getattr(self.get_queryset(), name)(*args, **kwargs)
  File "/Users/afsal/workspace/env_movie/lib/python2.7/site-packages/django/db/models/query.py", line 465, in get_or_create
    return self.get(**lookup), False
  File "/Users/afsal/workspace/env_movie/lib/python2.7/site-packages/django/db/models/query.py", line 378, in get
    clone = self.filter(*args, **kwargs)
  File "/Users/afsal/workspace/env_movie/lib/python2.7/site-packages/django/db/models/query.py", line 790, in filter
    return self._filter_or_exclude(False, *args, **kwargs)
  File "/Users/afsal/workspace/env_movie/lib/python2.7/site-packages/django/db/models/query.py", line 808, in _filter_or_exclude
    clone.query.add_q(Q(*args, **kwargs))
  File "/Users/afsal/workspace/env_movie/lib/python2.7/site-packages/django/db/models/sql/query.py", line 1243, in add_q
    clause, _ = self._add_q(q_object, self.used_aliases)
  File "/Users/afsal/workspace/env_movie/lib/python2.7/site-packages/django/db/models/sql/query.py", line 1269, in _add_q
    allow_joins=allow_joins, split_subq=split_subq,
  File "/Users/afsal/workspace/env_movie/lib/python2.7/site-packages/django/db/models/sql/query.py", line 1199, in build_filter
    condition = lookup_class(lhs, value)
  File "/Users/afsal/workspace/env_movie/lib/python2.7/site-packages/django/db/models/lookups.py", line 19, in __init__
    self.rhs = self.get_prep_lookup()
  File "/Users/afsal/workspace/env_movie/lib/python2.7/site-packages/django/db/models/fields/related_lookups.py", line 99, in get_prep_lookup
    self.lookup_name, self.rhs)
  File "/Users/afsal/workspace/env_movie/lib/python2.7/site-packages/django/db/models/fields/__init__.py", line 744, in get_prep_lookup
    return self.get_prep_value(value)
  File "/Users/afsal/workspace/env_movie/lib/python2.7/site-packages/django/db/models/fields/__init__.py", line 976, in get_prep_value
    return int(value)
TypeError: int() argument must be a string or a number, not 'Series'
[18/May/2018 18:23:27] ERROR [django.request:284] Internal Server Error: /
Traceback (most recent call last):
  File "/Users/afsal/workspace/env_movie/lib/python2.7/site-packages/django/core/handlers/base.py", line 149, in get_response
    response = self.process_exception_by_middleware(e, request)
  File "/Users/afsal/workspace/env_movie/lib/python2.7/site-packages/django/core/handlers/base.py", line 147, in get_response
    response = wrapped_callback(request, *callback_args, **callback_kwargs)
  File "/Users/afsal/workspace/movieList/app/home/views.py", line 17, in index
    season = Season.objects.get_or_create(series=series,url=url, name='Series '+str(i))
  File "/Users/afsal/workspace/env_movie/lib/python2.7/site-packages/django/db/models/manager.py", line 122, in manager_method
    return getattr(self.get_queryset(), name)(*args, **kwargs)
  File "/Users/afsal/workspace/env_movie/lib/python2.7/site-packages/django/db/models/query.py", line 465, in get_or_create
    return self.get(**lookup), False
  File "/Users/afsal/workspace/env_movie/lib/python2.7/site-packages/django/db/models/query.py", line 378, in get
    clone = self.filter(*args, **kwargs)
  File "/Users/afsal/workspace/env_movie/lib/python2.7/site-packages/django/db/models/query.py", line 790, in filter
    return self._filter_or_exclude(False, *args, **kwargs)
  File "/Users/afsal/workspace/env_movie/lib/python2.7/site-packages/django/db/models/query.py", line 808, in _filter_or_exclude
    clone.query.add_q(Q(*args, **kwargs))
  File "/Users/afsal/workspace/env_movie/lib/python2.7/site-packages/django/db/models/sql/query.py", line 1243, in add_q
    clause, _ = self._add_q(q_object, self.used_aliases)
  File "/Users/afsal/workspace/env_movie/lib/python2.7/site-packages/django/db/models/sql/query.py", line 1269, in _add_q
    allow_joins=allow_joins, split_subq=split_subq,
  File "/Users/afsal/workspace/env_movie/lib/python2.7/site-packages/django/db/models/sql/query.py", line 1199, in build_filter
    condition = lookup_class(lhs, value)
  File "/Users/afsal/workspace/env_movie/lib/python2.7/site-packages/django/db/models/lookups.py", line 19, in __init__
    self.rhs = self.get_prep_lookup()
  File "/Users/afsal/workspace/env_movie/lib/python2.7/site-packages/django/db/models/fields/related_lookups.py", line 99, in get_prep_lookup
    self.lookup_name, self.rhs)
  File "/Users/afsal/workspace/env_movie/lib/python2.7/site-packages/django/db/models/fields/__init__.py", line 744, in get_prep_lookup
    return self.get_prep_value(value)
  File "/Users/afsal/workspace/env_movie/lib/python2.7/site-packages/django/db/models/fields/__init__.py", line 976, in get_prep_value
    return int(value)
TypeError: int() argument must be a string or a number, not 'Series'
[18/May/2018 18:26:11] ERROR [django.request:284] Internal Server Error: /
Traceback (most recent call last):
  File "/Users/afsal/workspace/env_movie/lib/python2.7/site-packages/django/core/handlers/base.py", line 149, in get_response
    response = self.process_exception_by_middleware(e, request)
  File "/Users/afsal/workspace/env_movie/lib/python2.7/site-packages/django/core/handlers/base.py", line 147, in get_response
    response = wrapped_callback(request, *callback_args, **callback_kwargs)
  File "/Users/afsal/workspace/movieList/app/home/views.py", line 14, in index
    season_index = '{1:02d}'.format(i)
IndexError: tuple index out of range
[18/May/2018 18:26:48] ERROR [django.request:284] Internal Server Error: /
Traceback (most recent call last):
  File "/Users/afsal/workspace/env_movie/lib/python2.7/site-packages/django/core/handlers/base.py", line 149, in get_response
    response = self.process_exception_by_middleware(e, request)
  File "/Users/afsal/workspace/env_movie/lib/python2.7/site-packages/django/core/handlers/base.py", line 147, in get_response
    response = wrapped_callback(request, *callback_args, **callback_kwargs)
  File "/Users/afsal/workspace/movieList/app/home/views.py", line 18, in index
    season = Season.objects.get_or_create(series=series,url=url, name='Series {0}'.format(season_index))
  File "/Users/afsal/workspace/env_movie/lib/python2.7/site-packages/django/db/models/manager.py", line 122, in manager_method
    return getattr(self.get_queryset(), name)(*args, **kwargs)
  File "/Users/afsal/workspace/env_movie/lib/python2.7/site-packages/django/db/models/query.py", line 465, in get_or_create
    return self.get(**lookup), False
  File "/Users/afsal/workspace/env_movie/lib/python2.7/site-packages/django/db/models/query.py", line 378, in get
    clone = self.filter(*args, **kwargs)
  File "/Users/afsal/workspace/env_movie/lib/python2.7/site-packages/django/db/models/query.py", line 790, in filter
    return self._filter_or_exclude(False, *args, **kwargs)
  File "/Users/afsal/workspace/env_movie/lib/python2.7/site-packages/django/db/models/query.py", line 808, in _filter_or_exclude
    clone.query.add_q(Q(*args, **kwargs))
  File "/Users/afsal/workspace/env_movie/lib/python2.7/site-packages/django/db/models/sql/query.py", line 1243, in add_q
    clause, _ = self._add_q(q_object, self.used_aliases)
  File "/Users/afsal/workspace/env_movie/lib/python2.7/site-packages/django/db/models/sql/query.py", line 1269, in _add_q
    allow_joins=allow_joins, split_subq=split_subq,
  File "/Users/afsal/workspace/env_movie/lib/python2.7/site-packages/django/db/models/sql/query.py", line 1199, in build_filter
    condition = lookup_class(lhs, value)
  File "/Users/afsal/workspace/env_movie/lib/python2.7/site-packages/django/db/models/lookups.py", line 19, in __init__
    self.rhs = self.get_prep_lookup()
  File "/Users/afsal/workspace/env_movie/lib/python2.7/site-packages/django/db/models/fields/related_lookups.py", line 99, in get_prep_lookup
    self.lookup_name, self.rhs)
  File "/Users/afsal/workspace/env_movie/lib/python2.7/site-packages/django/db/models/fields/__init__.py", line 744, in get_prep_lookup
    return self.get_prep_value(value)
  File "/Users/afsal/workspace/env_movie/lib/python2.7/site-packages/django/db/models/fields/__init__.py", line 976, in get_prep_value
    return int(value)
TypeError: int() argument must be a string or a number, not 'Series'
[18/May/2018 18:27:44] ERROR [django.request:284] Internal Server Error: /
Traceback (most recent call last):
  File "/Users/afsal/workspace/env_movie/lib/python2.7/site-packages/django/core/handlers/base.py", line 149, in get_response
    response = self.process_exception_by_middleware(e, request)
  File "/Users/afsal/workspace/env_movie/lib/python2.7/site-packages/django/core/handlers/base.py", line 147, in get_response
    response = wrapped_callback(request, *callback_args, **callback_kwargs)
  File "/Users/afsal/workspace/movieList/app/home/views.py", line 23, in index
    link,created = Links.objects.get_or_create(series=series, url=url + anchor['href'])
  File "/Users/afsal/workspace/env_movie/lib/python2.7/site-packages/django/db/models/manager.py", line 122, in manager_method
    return getattr(self.get_queryset(), name)(*args, **kwargs)
  File "/Users/afsal/workspace/env_movie/lib/python2.7/site-packages/django/db/models/query.py", line 465, in get_or_create
    return self.get(**lookup), False
  File "/Users/afsal/workspace/env_movie/lib/python2.7/site-packages/django/db/models/query.py", line 378, in get
    clone = self.filter(*args, **kwargs)
  File "/Users/afsal/workspace/env_movie/lib/python2.7/site-packages/django/db/models/query.py", line 790, in filter
    return self._filter_or_exclude(False, *args, **kwargs)
  File "/Users/afsal/workspace/env_movie/lib/python2.7/site-packages/django/db/models/query.py", line 808, in _filter_or_exclude
    clone.query.add_q(Q(*args, **kwargs))
  File "/Users/afsal/workspace/env_movie/lib/python2.7/site-packages/django/db/models/sql/query.py", line 1243, in add_q
    clause, _ = self._add_q(q_object, self.used_aliases)
  File "/Users/afsal/workspace/env_movie/lib/python2.7/site-packages/django/db/models/sql/query.py", line 1269, in _add_q
    allow_joins=allow_joins, split_subq=split_subq,
  File "/Users/afsal/workspace/env_movie/lib/python2.7/site-packages/django/db/models/sql/query.py", line 1149, in build_filter
    lookups, parts, reffed_expression = self.solve_lookup_type(arg)
  File "/Users/afsal/workspace/env_movie/lib/python2.7/site-packages/django/db/models/sql/query.py", line 1035, in solve_lookup_type
    _, field, _, lookup_parts = self.names_to_path(lookup_splitted, self.get_meta())
  File "/Users/afsal/workspace/env_movie/lib/python2.7/site-packages/django/db/models/sql/query.py", line 1330, in names_to_path
    "Choices are: %s" % (name, ", ".join(available)))
FieldError: Cannot resolve keyword 'series' into field. Choices are: created_at, description, id, movie, name, season, slug_name, thumbnail, updated_at, url
[18/May/2018 18:28:21] ERROR [django.request:284] Internal Server Error: /
Traceback (most recent call last):
  File "/Users/afsal/workspace/env_movie/lib/python2.7/site-packages/django/core/handlers/base.py", line 149, in get_response
    response = self.process_exception_by_middleware(e, request)
  File "/Users/afsal/workspace/env_movie/lib/python2.7/site-packages/django/core/handlers/base.py", line 147, in get_response
    response = wrapped_callback(request, *callback_args, **callback_kwargs)
  File "/Users/afsal/workspace/movieList/app/home/views.py", line 23, in index
    link,created = Links.objects.get_or_create(series=series, url=url + anchor['href'])
  File "/Users/afsal/workspace/env_movie/lib/python2.7/site-packages/django/db/models/manager.py", line 122, in manager_method
    return getattr(self.get_queryset(), name)(*args, **kwargs)
  File "/Users/afsal/workspace/env_movie/lib/python2.7/site-packages/django/db/models/query.py", line 465, in get_or_create
    return self.get(**lookup), False
  File "/Users/afsal/workspace/env_movie/lib/python2.7/site-packages/django/db/models/query.py", line 378, in get
    clone = self.filter(*args, **kwargs)
  File "/Users/afsal/workspace/env_movie/lib/python2.7/site-packages/django/db/models/query.py", line 790, in filter
    return self._filter_or_exclude(False, *args, **kwargs)
  File "/Users/afsal/workspace/env_movie/lib/python2.7/site-packages/django/db/models/query.py", line 808, in _filter_or_exclude
    clone.query.add_q(Q(*args, **kwargs))
  File "/Users/afsal/workspace/env_movie/lib/python2.7/site-packages/django/db/models/sql/query.py", line 1243, in add_q
    clause, _ = self._add_q(q_object, self.used_aliases)
  File "/Users/afsal/workspace/env_movie/lib/python2.7/site-packages/django/db/models/sql/query.py", line 1269, in _add_q
    allow_joins=allow_joins, split_subq=split_subq,
  File "/Users/afsal/workspace/env_movie/lib/python2.7/site-packages/django/db/models/sql/query.py", line 1149, in build_filter
    lookups, parts, reffed_expression = self.solve_lookup_type(arg)
  File "/Users/afsal/workspace/env_movie/lib/python2.7/site-packages/django/db/models/sql/query.py", line 1035, in solve_lookup_type
    _, field, _, lookup_parts = self.names_to_path(lookup_splitted, self.get_meta())
  File "/Users/afsal/workspace/env_movie/lib/python2.7/site-packages/django/db/models/sql/query.py", line 1330, in names_to_path
    "Choices are: %s" % (name, ", ".join(available)))
FieldError: Cannot resolve keyword 'series' into field. Choices are: created_at, description, id, movie, name, season, slug_name, thumbnail, updated_at, url
[18/May/2018 18:28:55] ERROR [django.request:284] Internal Server Error: /
Traceback (most recent call last):
  File "/Users/afsal/workspace/env_movie/lib/python2.7/site-packages/django/core/handlers/base.py", line 149, in get_response
    response = self.process_exception_by_middleware(e, request)
  File "/Users/afsal/workspace/env_movie/lib/python2.7/site-packages/django/core/handlers/base.py", line 147, in get_response
    response = wrapped_callback(request, *callback_args, **callback_kwargs)
  File "/Users/afsal/workspace/movieList/app/home/views.py", line 23, in index
    link,created = Links.objects.get_or_create(season=season, url=url + anchor['href'])
  File "/Users/afsal/workspace/env_movie/lib/python2.7/site-packages/django/db/models/manager.py", line 122, in manager_method
    return getattr(self.get_queryset(), name)(*args, **kwargs)
  File "/Users/afsal/workspace/env_movie/lib/python2.7/site-packages/django/db/models/query.py", line 465, in get_or_create
    return self.get(**lookup), False
  File "/Users/afsal/workspace/env_movie/lib/python2.7/site-packages/django/db/models/query.py", line 381, in get
    num = len(clone)
  File "/Users/afsal/workspace/env_movie/lib/python2.7/site-packages/django/db/models/query.py", line 240, in __len__
    self._fetch_all()
  File "/Users/afsal/workspace/env_movie/lib/python2.7/site-packages/django/db/models/query.py", line 1074, in _fetch_all
    self._result_cache = list(self.iterator())
  File "/Users/afsal/workspace/env_movie/lib/python2.7/site-packages/django/db/models/query.py", line 52, in __iter__
    results = compiler.execute_sql()
  File "/Users/afsal/workspace/env_movie/lib/python2.7/site-packages/django/db/models/sql/compiler.py", line 848, in execute_sql
    cursor.execute(sql, params)
  File "/Users/afsal/workspace/env_movie/lib/python2.7/site-packages/django/db/backends/utils.py", line 79, in execute
    return super(CursorDebugWrapper, self).execute(sql, params)
  File "/Users/afsal/workspace/env_movie/lib/python2.7/site-packages/django/db/backends/utils.py", line 64, in execute
    return self.cursor.execute(sql, params)
  File "/Users/afsal/workspace/env_movie/lib/python2.7/site-packages/django/db/utils.py", line 95, in __exit__
    six.reraise(dj_exc_type, dj_exc_value, traceback)
  File "/Users/afsal/workspace/env_movie/lib/python2.7/site-packages/django/db/backends/utils.py", line 64, in execute
    return self.cursor.execute(sql, params)
ProgrammingError: relation "season_url_list" does not exist
LINE 1: ...at", "links"."updated_at" FROM "links" INNER JOIN "season_ur...
                                                             ^

[18/May/2018 18:31:17] ERROR [django.request:284] Internal Server Error: /
Traceback (most recent call last):
  File "/Users/afsal/workspace/env_movie/lib/python2.7/site-packages/django/core/handlers/base.py", line 149, in get_response
    response = self.process_exception_by_middleware(e, request)
  File "/Users/afsal/workspace/env_movie/lib/python2.7/site-packages/django/core/handlers/base.py", line 147, in get_response
    response = wrapped_callback(request, *callback_args, **callback_kwargs)
  File "/Users/afsal/workspace/movieList/app/home/views.py", line 23, in index
    link, created = Links.objects.get_or_create(season=season, url=url + anchor['href'])
  File "/Users/afsal/workspace/env_movie/lib/python2.7/site-packages/django/db/models/manager.py", line 122, in manager_method
    return getattr(self.get_queryset(), name)(*args, **kwargs)
  File "/Users/afsal/workspace/env_movie/lib/python2.7/site-packages/django/db/models/query.py", line 465, in get_or_create
    return self.get(**lookup), False
  File "/Users/afsal/workspace/env_movie/lib/python2.7/site-packages/django/db/models/query.py", line 381, in get
    num = len(clone)
  File "/Users/afsal/workspace/env_movie/lib/python2.7/site-packages/django/db/models/query.py", line 240, in __len__
    self._fetch_all()
  File "/Users/afsal/workspace/env_movie/lib/python2.7/site-packages/django/db/models/query.py", line 1074, in _fetch_all
    self._result_cache = list(self.iterator())
  File "/Users/afsal/workspace/env_movie/lib/python2.7/site-packages/django/db/models/query.py", line 52, in __iter__
    results = compiler.execute_sql()
  File "/Users/afsal/workspace/env_movie/lib/python2.7/site-packages/django/db/models/sql/compiler.py", line 848, in execute_sql
    cursor.execute(sql, params)
  File "/Users/afsal/workspace/env_movie/lib/python2.7/site-packages/django/db/backends/utils.py", line 79, in execute
    return super(CursorDebugWrapper, self).execute(sql, params)
  File "/Users/afsal/workspace/env_movie/lib/python2.7/site-packages/django/db/backends/utils.py", line 64, in execute
    return self.cursor.execute(sql, params)
  File "/Users/afsal/workspace/env_movie/lib/python2.7/site-packages/django/db/utils.py", line 95, in __exit__
    six.reraise(dj_exc_type, dj_exc_value, traceback)
  File "/Users/afsal/workspace/env_movie/lib/python2.7/site-packages/django/db/backends/utils.py", line 64, in execute
    return self.cursor.execute(sql, params)
ProgrammingError: relation "season_url_list" does not exist
LINE 1: ...at", "links"."updated_at" FROM "links" INNER JOIN "season_ur...
                                                             ^

[18/May/2018 18:32:18] ERROR [django.request:284] Internal Server Error: /
Traceback (most recent call last):
  File "/Users/afsal/workspace/env_movie/lib/python2.7/site-packages/django/core/handlers/base.py", line 149, in get_response
    response = self.process_exception_by_middleware(e, request)
  File "/Users/afsal/workspace/env_movie/lib/python2.7/site-packages/django/core/handlers/base.py", line 147, in get_response
    response = wrapped_callback(request, *callback_args, **callback_kwargs)
  File "/Users/afsal/workspace/movieList/app/home/views.py", line 23, in index
    link, created = Links.objects.get_or_create(season=season, url=url + anchor['href'])
  File "/Users/afsal/workspace/env_movie/lib/python2.7/site-packages/django/db/models/manager.py", line 122, in manager_method
    return getattr(self.get_queryset(), name)(*args, **kwargs)
  File "/Users/afsal/workspace/env_movie/lib/python2.7/site-packages/django/db/models/query.py", line 465, in get_or_create
    return self.get(**lookup), False
  File "/Users/afsal/workspace/env_movie/lib/python2.7/site-packages/django/db/models/query.py", line 381, in get
    num = len(clone)
  File "/Users/afsal/workspace/env_movie/lib/python2.7/site-packages/django/db/models/query.py", line 240, in __len__
    self._fetch_all()
  File "/Users/afsal/workspace/env_movie/lib/python2.7/site-packages/django/db/models/query.py", line 1074, in _fetch_all
    self._result_cache = list(self.iterator())
  File "/Users/afsal/workspace/env_movie/lib/python2.7/site-packages/django/db/models/query.py", line 52, in __iter__
    results = compiler.execute_sql()
  File "/Users/afsal/workspace/env_movie/lib/python2.7/site-packages/django/db/models/sql/compiler.py", line 848, in execute_sql
    cursor.execute(sql, params)
  File "/Users/afsal/workspace/env_movie/lib/python2.7/site-packages/django/db/backends/utils.py", line 79, in execute
    return super(CursorDebugWrapper, self).execute(sql, params)
  File "/Users/afsal/workspace/env_movie/lib/python2.7/site-packages/django/db/backends/utils.py", line 64, in execute
    return self.cursor.execute(sql, params)
  File "/Users/afsal/workspace/env_movie/lib/python2.7/site-packages/django/db/utils.py", line 95, in __exit__
    six.reraise(dj_exc_type, dj_exc_value, traceback)
  File "/Users/afsal/workspace/env_movie/lib/python2.7/site-packages/django/db/backends/utils.py", line 64, in execute
    return self.cursor.execute(sql, params)
ProgrammingError: relation "season_url_list" does not exist
LINE 1: ...at", "links"."updated_at" FROM "links" INNER JOIN "season_ur...
                                                             ^

[18/May/2018 18:33:05] ERROR [django.request:284] Internal Server Error: /
Traceback (most recent call last):
  File "/Users/afsal/workspace/env_movie/lib/python2.7/site-packages/django/core/handlers/base.py", line 149, in get_response
    response = self.process_exception_by_middleware(e, request)
  File "/Users/afsal/workspace/env_movie/lib/python2.7/site-packages/django/core/handlers/base.py", line 147, in get_response
    response = wrapped_callback(request, *callback_args, **callback_kwargs)
  File "/Users/afsal/workspace/movieList/app/home/views.py", line 26, in index
    season.url_list.add(link)
  File "/Users/afsal/workspace/env_movie/lib/python2.7/site-packages/django/db/models/fields/related_descriptors.py", line 843, in add
    self._add_items(self.source_field_name, self.target_field_name, *objs)
  File "/Users/afsal/workspace/env_movie/lib/python2.7/site-packages/django/db/models/fields/related_descriptors.py", line 988, in _add_items
    new_ids = new_ids - set(vals)
  File "/Users/afsal/workspace/env_movie/lib/python2.7/site-packages/django/db/models/query.py", line 258, in __iter__
    self._fetch_all()
  File "/Users/afsal/workspace/env_movie/lib/python2.7/site-packages/django/db/models/query.py", line 1074, in _fetch_all
    self._result_cache = list(self.iterator())
  File "/Users/afsal/workspace/env_movie/lib/python2.7/site-packages/django/db/models/query.py", line 158, in __iter__
    for row in compiler.results_iter():
  File "/Users/afsal/workspace/env_movie/lib/python2.7/site-packages/django/db/models/sql/compiler.py", line 802, in results_iter
    results = self.execute_sql(MULTI)
  File "/Users/afsal/workspace/env_movie/lib/python2.7/site-packages/django/db/models/sql/compiler.py", line 848, in execute_sql
    cursor.execute(sql, params)
  File "/Users/afsal/workspace/env_movie/lib/python2.7/site-packages/django/db/backends/utils.py", line 79, in execute
    return super(CursorDebugWrapper, self).execute(sql, params)
  File "/Users/afsal/workspace/env_movie/lib/python2.7/site-packages/django/db/backends/utils.py", line 64, in execute
    return self.cursor.execute(sql, params)
  File "/Users/afsal/workspace/env_movie/lib/python2.7/site-packages/django/db/utils.py", line 95, in __exit__
    six.reraise(dj_exc_type, dj_exc_value, traceback)
  File "/Users/afsal/workspace/env_movie/lib/python2.7/site-packages/django/db/backends/utils.py", line 64, in execute
    return self.cursor.execute(sql, params)
ProgrammingError: relation "season_url_list" does not exist
LINE 1: SELECT "season_url_list"."links_id" FROM "season_url_list" W...
                                                 ^

